<?xml version="1.0" ?>
<!-- =================================================================================== -->
<!-- |    This document was autogenerated by xacro from rg6_gripper.xacro              | -->
<!-- |    EDITING THIS FILE BY HAND IS NOT RECOMMENDED                                 | -->
<!-- =================================================================================== -->
<robot name="rg6">
  <material name="silver">
    <color rgba="0.700 0.700 0.700 1.000"/>
  </material>
  <transmission name="g_main_tran">
    <type>transmission_interface/SimpleTransmission</type>
    <joint name="g_main">
      <hardwareInterface>hardware_interface/EffortJointInterface</hardwareInterface>
    </joint>
    <actuator name="g_main_actr">
      <hardwareInterface>hardware_interface/EffortJointInterface</hardwareInterface>
      <mechanicalReduction>1</mechanicalReduction>
    </actuator>
  </transmission>
  <transmission name="l_out_tran">
    <type>transmission_interface/SimpleTransmission</type>
    <joint name="l_out">
      <hardwareInterface>hardware_interface/EffortJointInterface</hardwareInterface>
    </joint>
    <actuator name="l_out_actr">
      <hardwareInterface>hardware_interface/EffortJointInterface</hardwareInterface>
      <mechanicalReduction>1</mechanicalReduction>
    </actuator>
  </transmission>
  <transmission name="r_out_tran">
    <type>transmission_interface/SimpleTransmission</type>
    <joint name="r_out">
      <hardwareInterface>hardware_interface/EffortJointInterface</hardwareInterface>
    </joint>
    <actuator name="r_out_actr">
      <hardwareInterface>hardware_interface/EffortJointInterface</hardwareInterface>
      <mechanicalReduction>1</mechanicalReduction>
    </actuator>
  </transmission>
  <transmission name="l_tip_tran">
    <type>transmission_interface/SimpleTransmission</type>
    <joint name="l_tip">
      <hardwareInterface>hardware_interface/EffortJointInterface</hardwareInterface>
    </joint>
    <actuator name="l_tip_actr">
      <hardwareInterface>hardware_interface/EffortJointInterface</hardwareInterface>
      <mechanicalReduction>1</mechanicalReduction>
    </actuator>
  </transmission>
  <transmission name="r_tip_tran">
    <type>transmission_interface/SimpleTransmission</type>
    <joint name="r_tip">
      <hardwareInterface>hardware_interface/EffortJointInterface</hardwareInterface>
    </joint>
    <actuator name="r_tip_actr">
      <hardwareInterface>hardware_interface/EffortJointInterface</hardwareInterface>
      <mechanicalReduction>1</mechanicalReduction>
    </actuator>
  </transmission>
  <transmission name="l_passive_tran">
    <type>transmission_interface/SimpleTransmission</type>
    <joint name="l_passive">
      <hardwareInterface>hardware_interface/EffortJointInterface</hardwareInterface>
    </joint>
    <actuator name="l_passive_actr">
      <hardwareInterface>hardware_interface/EffortJointInterface</hardwareInterface>
      <mechanicalReduction>1</mechanicalReduction>
    </actuator>
  </transmission>
  <transmission name="r_passive_tran">
    <type>transmission_interface/SimpleTransmission</type>
    <joint name="r_passive">
      <hardwareInterface>hardware_interface/EffortJointInterface</hardwareInterface>
    </joint>
    <actuator name="r_passive_actr">
      <hardwareInterface>hardware_interface/EffortJointInterface</hardwareInterface>
      <mechanicalReduction>1</mechanicalReduction>
    </actuator>
  </transmission>
  <gazebo>
    <plugin filename="libgazebo_ros_control.so" name="control"/>
  </gazebo>
  <gazebo reference="base_link">
    <material>Gazebo/Silver</material>
    <mu1>0.2</mu1>
    <mu2>0.2</mu2>
    <selfCollide>true</selfCollide>
    <gravity>true</gravity>
  </gazebo>
  <gazebo reference="g_main">
    <material>Gazebo/Silver</material>
    <mu1>0.2</mu1>
    <mu2>0.2</mu2>
    <selfCollide>true</selfCollide>
  </gazebo>
  <gazebo reference="l_out">
    <material>Gazebo/Silver</material>
    <mu1>0.2</mu1>
    <mu2>0.2</mu2>
    <selfCollide>true</selfCollide>
  </gazebo>
  <gazebo reference="r_out">
    <material>Gazebo/Silver</material>
    <mu1>0.2</mu1>
    <mu2>0.2</mu2>
    <selfCollide>true</selfCollide>
  </gazebo>
  <gazebo reference="l_tip">
    <material>Gazebo/Silver</material>
    <mu1>0.2</mu1>
    <mu2>0.2</mu2>
    <selfCollide>true</selfCollide>
  </gazebo>
  <gazebo reference="r_tip">
    <material>Gazebo/Silver</material>
    <mu1>0.2</mu1>
    <mu2>0.2</mu2>
    <selfCollide>true</selfCollide>
  </gazebo>
  <gazebo reference="l_inner">
    <material>Gazebo/Silver</material>
    <mu1>0.2</mu1>
    <mu2>0.2</mu2>
    <selfCollide>true</selfCollide>
  </gazebo>
  <gazebo reference="r_inner">
    <material>Gazebo/Silver</material>
    <mu1>0.2</mu1>
    <mu2>0.2</mu2>
    <selfCollide>true</selfCollide>
  </gazebo>
  <link name="base_link">
    <inertial>
      <origin rpy="0 0 0" xyz="-0.00030179080386336256 -0.00047670368310389217 0.020678912231015475"/>
      <mass value="0.7592453895368185"/>
      <inertia ixx="0.000452" ixy="-1e-06" ixz="-0.0" iyy="0.000705" iyz="-5e-06" izz="0.000689"/>
    </inertial>
    <visual>
      <origin rpy="0 0 0" xyz="0 0 0"/>
      <geometry>
        <mesh filename="package://rg6_gripper_description/meshes/base_link.stl" scale="0.001 0.001 0.001"/>
      </geometry>
      <material name="silver"/>
    </visual>
    <collision>
      <origin rpy="0 0 0" xyz="0 0 0"/>
      <geometry>
        <mesh filename="package://rg6_gripper_description/meshes/base_link.stl" scale="0.001 0.001 0.001"/>
      </geometry>
    </collision>
  </link>
  <link name="g_main">
    <inertial>
      <origin rpy="0 0 0" xyz="0.031843851343412694 -6.562152034605188e-05 0.0402561266087614"/>
      <mass value="2.1746665575894286"/>
      <inertia ixx="0.003297" ixy="-1e-06" ixz="3e-06" iyy="0.00361" iyz="5e-06" izz="0.00105"/>
    </inertial>
    <visual>
      <origin rpy="0 0 0" xyz="0.031849 -1e-06 -0.04953"/>
      <geometry>
        <mesh filename="package://rg6_gripper_description/meshes/g_main.stl" scale="0.001 0.001 0.001"/>
      </geometry>
      <material name="silver"/>
    </visual>
    <collision>
      <origin rpy="0 0 0" xyz="0.031849 -1e-06 -0.04953"/>
      <geometry>
        <mesh filename="package://rg6_gripper_description/meshes/g_main.stl" scale="0.001 0.001 0.001"/>
      </geometry>
    </collision>
  </link>
  <link name="l_out">
    <inertial>
      <origin rpy="0 0 0" xyz="0.010442859349590227 -0.012799625869821 0.012792983853972317"/>
      <mass value="0.24195762212403002"/>
      <inertia ixx="0.00011" ixy="0.0" ixz="-6.6e-05" iyy="0.00016" iyz="0.0" izz="7.6e-05"/>
    </inertial>
    <visual>
      <origin rpy="0 0 0" xyz="-0.023851 -0.012801 -0.13453"/>
      <geometry>
        <mesh filename="package://rg6_gripper_description/meshes/l_out.stl" scale="0.001 0.001 0.001"/>
      </geometry>
      <material name="silver"/>
    </visual>
    <collision>
      <origin rpy="0 0 0" xyz="-0.023851 -0.012801 -0.13453"/>
      <geometry>
        <mesh filename="package://rg6_gripper_description/meshes/l_out.stl" scale="0.001 0.001 0.001"/>
      </geometry>
    </collision>
  </link>
  <link name="r_out">
    <inertial>
      <origin rpy="0 0 0" xyz="-0.010522665986501832 -0.012799489922871823 0.012809246687502496"/>
      <mass value="0.24195762035711757"/>
      <inertia ixx="0.00011" ixy="0.0" ixz="6.5e-05" iyy="0.00016" iyz="-0.0" izz="7.6e-05"/>
    </inertial>
    <visual>
      <origin rpy="0 0 0" xyz="0.023749 -0.012801 -0.13453"/>
      <geometry>
        <mesh filename="package://rg6_gripper_description/meshes/r_out.stl" scale="0.001 0.001 0.001"/>
      </geometry>
      <material name="silver"/>
    </visual>
    <collision>
      <origin rpy="0 0 0" xyz="0.023749 -0.012801 -0.13453"/>
      <geometry>
        <mesh filename="package://rg6_gripper_description/meshes/r_out.stl" scale="0.001 0.001 0.001"/>
      </geometry>
    </collision>
  </link>
  <link name="l_tip">
    <inertial>
      <origin rpy="0 0 0" xyz="-0.01379426979129901 0.012430443916766657 0.03303967984911002"/>
      <mass value="0.13426652162693567"/>
      <inertia ixx="5.6e-05" ixy="-0.0" ixz="1.6e-05" iyy="5.9e-05" iyz="-0.0" izz="1.3e-05"/>
    </inertial>
    <visual>
      <origin rpy="0 0 0" xyz="-0.071235 0.012499 -0.19895"/>
      <geometry>
        <mesh filename="package://rg6_gripper_description/meshes/l_tip.stl" scale="0.001 0.001 0.001"/>
      </geometry>
      <material name="silver"/>
    </visual>
    <collision>
      <origin rpy="0 0 0" xyz="-0.071235 0.012499 -0.19895"/>
      <geometry>
        <mesh filename="package://rg6_gripper_description/meshes/l_tip.stl" scale="0.001 0.001 0.001"/>
      </geometry>
    </collision>
  </link>
  <link name="r_tip">
    <inertial>
      <origin rpy="0 0 0" xyz="0.01379460286375201 0.012599371946431372 0.03303919214417522"/>
      <mass value="0.13426652162693592"/>
      <inertia ixx="5.6e-05" ixy="-0.0" ixz="-1.6e-05" iyy="5.9e-05" iyz="-0.0" izz="1.3e-05"/>
    </inertial>
    <visual>
      <origin rpy="0 0 0" xyz="0.071133 0.012499 -0.199024"/>
      <geometry>
        <mesh filename="package://rg6_gripper_description/meshes/r_tip.stl" scale="0.001 0.001 0.001"/>
      </geometry>
      <material name="silver"/>
    </visual>
    <collision>
      <origin rpy="0 0 0" xyz="0.071133 0.012499 -0.199024"/>
      <geometry>
        <mesh filename="package://rg6_gripper_description/meshes/r_tip.stl" scale="0.001 0.001 0.001"/>
      </geometry>
    </collision>
  </link>
  <link name="l_inner">
    <inertial>
      <origin rpy="0 0 0" xyz="0.021220873634115123 -0.00019955790008889003 0.02884270588361451"/>
      <mass value="0.0502402669834145"/>
      <inertia ixx="3.4e-05" ixy="-0.0" ixz="-2.2e-05" iyy="4.6e-05" iyz="-0.0" izz="2e-05"/>
    </inertial>
    <visual>
      <origin rpy="0 0 0" xyz="-0.010551 -0.000101 -0.15763"/>
      <geometry>
        <mesh filename="package://rg6_gripper_description/meshes/l_inner.stl" scale="0.001 0.001 0.001"/>
      </geometry>
      <material name="silver"/>
    </visual>
    <collision>
      <origin rpy="0 0 0" xyz="-0.010551 -0.000101 -0.15763"/>
      <geometry>
        <mesh filename="package://rg6_gripper_description/meshes/l_inner.stl" scale="0.001 0.001 0.001"/>
      </geometry>
    </collision>
  </link>
  <link name="r_inner">
    <inertial>
      <origin rpy="0 0 0" xyz="-0.021275767636285234 -0.00019955790008339296 0.02887567083082221"/>
      <mass value="0.05024026698344974"/>
      <inertia ixx="3.4e-05" ixy="-0.0" ixz="2.2e-05" iyy="4.6e-05" iyz="0.0" izz="2e-05"/>
    </inertial>
    <visual>
      <origin rpy="0 0 0" xyz="0.010449 -0.000101 -0.15763"/>
      <geometry>
        <mesh filename="package://rg6_gripper_description/meshes/r_inner.stl" scale="0.001 0.001 0.001"/>
      </geometry>
      <material name="silver"/>
    </visual>
    <collision>
      <origin rpy="0 0 0" xyz="0.010449 -0.000101 -0.15763"/>
      <geometry>
        <mesh filename="package://rg6_gripper_description/meshes/r_inner.stl" scale="0.001 0.001 0.001"/>
      </geometry>
    </collision>
  </link>
  <joint name="g_main" type="fixed">
    <origin rpy="0 0 0" xyz="-0.031849 1e-06 0.04953"/>
    <parent link="base_link"/>
    <child link="g_main"/>
  </joint>
  <joint name="l_out" type="revolute">
    <origin rpy="0 0 0" xyz="0.0557 0.0128 0.085"/>
    <parent link="g_main"/>
    <child link="l_out"/>
    <axis xyz="-0.0 1.0 0.0"/>
    <limit effort="100" lower="-0.75" upper="0.610865" velocity="100"/>
  </joint>
  <joint name="r_out" type="revolute">
    <origin rpy="0 0 0" xyz="0.0081 0.0128 0.085"/>
    <parent link="g_main"/>
    <child link="r_out"/>
    <axis xyz="-0.0 1.0 0.0"/>
    <limit effort="100" lower="-0.610865" upper="0.523599" velocity="100"/>
    <mimic joint="l_out" multiplier="-1"/>
  </joint>
  <joint name="l_tip" type="revolute">
    <origin rpy="0 0 0" xyz="0.047384 -0.0253 0.06442"/>
    <parent link="l_out"/>
    <child link="l_tip"/>
    <axis xyz="0.0 -1.0 0.0"/>
    <limit effort="100" lower="-0.523599" upper="0.610865" velocity="100"/>
    <mimic joint="l_out" multiplier="1"/>
  </joint>
  <joint name="r_tip" type="revolute">
    <origin rpy="0 0 0" xyz="-0.047384 -0.0253 0.064494"/>
    <parent link="r_out"/>
    <child link="r_tip"/>
    <axis xyz="0.0 -1.0 0.0"/>
    <limit effort="100" lower="-0.610865" upper="0.523599" velocity="100"/>
    <mimic joint="l_out" multiplier="-1"/>
  </joint>
  <joint name="l_passive" type="revolute">
    <origin rpy="0 0 0" xyz="0.0424 0.0001 0.1081"/>
    <parent link="g_main"/>
    <child link="l_inner"/>
    <axis xyz="0.0 -1.0 0.0"/>
    <limit effort="100" lower="-0.610865" upper="0.523599" velocity="100"/>
    <mimic joint="l_out" multiplier="-1"/>
  </joint>
  <joint name="r_passive" type="revolute">
    <origin rpy="0 0 0" xyz="0.0214 0.0001 0.1081"/>
    <parent link="g_main"/>
    <child link="r_inner"/>
    <axis xyz="-0.0 1.0 -0.0"/>
    <limit effort="100" lower="-0.610865" upper="0.523599" velocity="100"/>
    <mimic joint="l_out" multiplier="-1"/>
  </joint>
  <link name="hand_tcp"/>
  <joint name="hand_tcp_joint" type="fixed">
    <origin rpy="0 0 0" xyz="0.036 0 0.21"/>
    <parent link="g_main"/>
    <child link="hand_tcp"/>
    <axis xyz="-0.0 1.0 -0.0"/>
  </joint>
</robot>
